<?xml version='1.0' encoding='utf-8'?>
<robot name="FullBodyModel_MuscleActuatedLowerLimb_TorqueActuatedUpperBody_converted">
  <mujoco>
    <compiler meshdir="./Geometry" balanceinertia="true" discardvisual="false" fusestatic="true" />
  </mujoco>
  <!-- Converted from Rajagopal2015.osim. OpenSim Y-up data was re-expressed into URDF Z-up coordinates. -->
  <!-- Coupled transforms that URDF cannot represent directly are frozen at the OpenSim default coordinate value. -->
  <link name="ground">
    <inertial>
      <origin xyz="0 0 0" rpy="0 0 0" />
      <mass value="0.001" />
      <inertia ixx="1e-06" ixy="0" ixz="0" iyy="1e-06" iyz="0" izz="1e-06" />
    </inertial>
  </link>
  <joint name="pelvis_tx" type="prismatic">
    <origin xyz="0 0 0" rpy="0 0 0" />
    <parent link="ground" />
    <child link="pelvis_tx_link" />
    <axis xyz="1 0 0" />
    <limit effort="1000" velocity="5" lower="-5" upper="5" />
  </joint>
  <link name="pelvis_tx_link">
    <inertial>
      <origin xyz="0 0 0" rpy="0 0 0" />
      <mass value="0.001" />
      <inertia ixx="1e-06" ixy="0" ixz="0" iyy="1e-06" iyz="0" izz="1e-06" />
    </inertial>
  </link>
  <joint name="pelvis_ty" type="prismatic">
    <origin xyz="0 0 0" rpy="0 0 0" />
    <parent link="pelvis_tx_link" />
    <child link="pelvis_ty_link" />
    <axis xyz="0 1 0" />
    <limit effort="1000" velocity="5" lower="-1" upper="2" />
  </joint>
  <link name="pelvis_ty_link">
    <inertial>
      <origin xyz="0 0 0" rpy="0 0 0" />
      <mass value="0.001" />
      <inertia ixx="1e-06" ixy="0" ixz="0" iyy="1e-06" iyz="0" izz="1e-06" />
    </inertial>
  </link>
  <joint name="pelvis_tz" type="prismatic">
    <origin xyz="0 0 0" rpy="0 0 0" />
    <parent link="pelvis_ty_link" />
    <child link="pelvis_tz_link" />
    <axis xyz="0 0 1" />
    <limit effort="1000" velocity="5" lower="-3" upper="3" />
  </joint>
  <link name="pelvis_tz_link">
    <inertial>
      <origin xyz="0 0 0" rpy="0 0 0" />
      <mass value="0.001" />
      <inertia ixx="1e-06" ixy="0" ixz="0" iyy="1e-06" iyz="0" izz="1e-06" />
    </inertial>
  </link>
  <joint name="pelvis_tilt" type="revolute">
    <origin xyz="0 0 0" rpy="0 0 0" />
    <parent link="pelvis_tz_link" />
    <child link="pelvis_tilt_link" />
    <axis xyz="0 0 1" />
    <limit effort="1000" velocity="10" lower="-1.57079633" upper="1.57079633" />
  </joint>
  <link name="pelvis_tilt_link">
    <inertial>
      <origin xyz="0 0 0" rpy="0 0 0" />
      <mass value="0.001" />
      <inertia ixx="1e-06" ixy="0" ixz="0" iyy="1e-06" iyz="0" izz="1e-06" />
    </inertial>
  </link>
  <joint name="pelvis_list" type="revolute">
    <origin xyz="0 0 0" rpy="0 0 0" />
    <parent link="pelvis_tilt_link" />
    <child link="pelvis_list_link" />
    <axis xyz="1 0 0" />
    <limit effort="1000" velocity="10" lower="-1.57079633" upper="1.57079633" />
  </joint>
  <link name="pelvis_list_link">
    <inertial>
      <origin xyz="0 0 0" rpy="0 0 0" />
      <mass value="0.001" />
      <inertia ixx="1e-06" ixy="0" ixz="0" iyy="1e-06" iyz="0" izz="1e-06" />
    </inertial>
  </link>
  <joint name="pelvis_rotation" type="revolute">
    <origin xyz="0 0 0" rpy="0 0 0" />
    <parent link="pelvis_list_link" />
    <child link="pelvis_rotation_link" />
    <axis xyz="0 1 0" />
    <limit effort="1000" velocity="10" lower="-1.57079633" upper="1.57079633" />
  </joint>
  <link name="pelvis_rotation_link">
    <inertial>
      <origin xyz="0 0 0" rpy="0 0 0" />
      <mass value="0.001" />
      <inertia ixx="1e-06" ixy="0" ixz="0" iyy="1e-06" iyz="0" izz="1e-06" />
    </inertial>
  </link>
  <joint name="pelvis_fixed" type="fixed">
    <origin xyz="0 0 0" rpy="0 0 0" />
    <parent link="pelvis_rotation_link" />
    <child link="pelvis" />
  </joint>
  <link name="pelvis">
    <inertial>
      <origin xyz="-0.0707 0 0" rpy="0 0 0" />
      <mass value="11.777" />
      <inertia ixx="0.1028" ixy="0" ixz="0" iyy="0.0579" iyz="0" izz="0.0871" />
    </inertial>
    <visual name="pelvis_visual_0">
      <origin xyz="0 0 0" rpy="1.57079633 0 0" />
      <geometry>
        <mesh filename="Geometry/r_pelvis.obj" scale="1 1 1" />
      </geometry>
      <material name="pelvis_material_0">
        <color rgba="1 1 1 1" />
      </material>
    </visual>
    <visual name="pelvis_visual_1">
      <origin xyz="0 0 0" rpy="1.57079633 0 0" />
      <geometry>
        <mesh filename="Geometry/l_pelvis.obj" scale="1 1 1" />
      </geometry>
      <material name="pelvis_material_1">
        <color rgba="1 1 1 1" />
      </material>
    </visual>
    <visual name="pelvis_visual_2">
      <origin xyz="0 0 0" rpy="1.57079633 0 0" />
      <geometry>
        <mesh filename="Geometry/sacrum.obj" scale="1 1 1" />
      </geometry>
      <material name="pelvis_material_2">
        <color rgba="1 1 1 1" />
      </material>
    </visual>
  </link>
  <joint name="hip_flexion_r" type="revolute">
    <origin xyz="-0.056276 -0.07726 -0.07849" rpy="0 0 0" />
    <parent link="pelvis" />
    <child link="hip_flexion_r_link" />
    <axis xyz="0 -1 0" />
    <limit effort="1000" velocity="10" lower="-0.52359878" upper="2.0943951" />
  </joint>
  <link name="hip_flexion_r_link">
    <inertial>
      <origin xyz="0 0 0" rpy="0 0 0" />
      <mass value="0.001" />
      <inertia ixx="1e-06" ixy="0" ixz="0" iyy="1e-06" iyz="0" izz="1e-06" />
    </inertial>
  </link>
  <joint name="hip_adduction_r" type="revolute">
    <origin xyz="0 0 0" rpy="0 0 0" />
    <parent link="hip_flexion_r_link" />
    <child link="hip_adduction_r_link" />
    <axis xyz="1 0 0" />
    <limit effort="1000" velocity="10" lower="-0.87266463" upper="0.52359878" />
  </joint>
  <link name="hip_adduction_r_link">
    <inertial>
      <origin xyz="0 0 0" rpy="0 0 0" />
      <mass value="0.001" />
      <inertia ixx="1e-06" ixy="0" ixz="0" iyy="1e-06" iyz="0" izz="1e-06" />
    </inertial>
  </link>
  <joint name="hip_rotation_r" type="revolute">
    <origin xyz="0 0 0" rpy="0 0 0" />
    <parent link="hip_adduction_r_link" />
    <child link="hip_rotation_r_link" />
    <axis xyz="0 0 1" />
    <limit effort="1000" velocity="10" lower="-0.6981317" upper="0.6981317" />
  </joint>
  <link name="hip_rotation_r_link">
    <inertial>
      <origin xyz="0 0 0" rpy="0 0 0" />
      <mass value="0.001" />
      <inertia ixx="1e-06" ixy="0" ixz="0" iyy="1e-06" iyz="0" izz="1e-06" />
    </inertial>
  </link>
  <joint name="femur_r_fixed" type="fixed">
    <origin xyz="0 0 0" rpy="0 0 0" />
    <parent link="hip_rotation_r_link" />
    <child link="femur_r" />
  </joint>
  <link name="femur_r">
    <inertial>
      <origin xyz="0 0 -0.17" rpy="0 0 0" />
      <mass value="9.3014" />
      <inertia ixx="0.1339" ixy="0" ixz="0" iyy="0.1412" iyz="0" izz="0.0351" />
    </inertial>
    <visual name="femur_r_visual_0">
      <origin xyz="0 0 0" rpy="1.57079633 0 0" />
      <geometry>
        <mesh filename="Geometry/r_femur.obj" scale="1 1 1" />
      </geometry>
      <material name="femur_r_material_0">
        <color rgba="1 1 1 1" />
      </material>
    </visual>
  </link>
  <joint name="knee_angle_r" type="revolute">
    <origin xyz="-0.00809 0.00275 -0.40796" rpy="-0.124615527 0.07077216 1.57079633" />
    <parent link="femur_r" />
    <child link="knee_angle_r_link" />
    <axis xyz="1 0 0" />
    <limit effort="1000" velocity="10" lower="0" upper="2.0944" />
  </joint>
  <link name="knee_angle_r_link">
    <inertial>
      <origin xyz="0 0 0" rpy="0 0 0" />
      <mass value="0.001" />
      <inertia ixx="1e-06" ixy="0" ixz="0" iyy="1e-06" iyz="0" izz="1e-06" />
    </inertial>
  </link>
  <joint name="tibia_r_fixed" type="fixed">
    <origin xyz="-0.0017309799 -0.00845201222 0.00238895779" rpy="0.07077216 0.124615527 -1.57079633" />
    <parent link="knee_angle_r_link" />
    <child link="tibia_r" />
  </joint>
  <link name="tibia_r">
    <inertial>
      <origin xyz="0 0 -0.1867" rpy="0 0 0" />
      <mass value="3.7075" />
      <inertia ixx="0.0504" ixy="0" ixz="0" iyy="0.0511" iyz="0" izz="0.0051" />
    </inertial>
    <visual name="tibia_r_visual_0">
      <origin xyz="0 0 0" rpy="1.57079633 0 0" />
      <geometry>
        <mesh filename="Geometry/r_tibia.obj" scale="1 1 1" />
      </geometry>
      <material name="tibia_r_material_0">
        <color rgba="1 1 1 1" />
      </material>
    </visual>
    <visual name="tibia_r_visual_1">
      <origin xyz="0 0 0" rpy="1.57079633 0 0" />
      <geometry>
        <mesh filename="Geometry/r_fibula.obj" scale="1 1 1" />
      </geometry>
      <material name="tibia_r_material_1">
        <color rgba="1 1 1 1" />
      </material>
    </visual>
  </link>
  <joint name="patella_r_fixed" type="fixed">
    <origin xyz="0.0443222442 -0.00799042157 -0.40521" rpy="0 0 0.00113686" />
    <parent link="femur_r" />
    <child link="patella_r" />
  </joint>
  <link name="patella_r">
    <inertial>
      <origin xyz="0.0018 0 0.0264" rpy="0 0 0" />
      <mass value="0.0862" />
      <inertia ixx="2.87e-06" ixy="0" ixz="0" iyy="1.311e-05" iyz="0" izz="1.311e-05" />
    </inertial>
    <visual name="patella_r_visual_0">
      <origin xyz="0 0 0" rpy="1.57079633 0 0" />
      <geometry>
        <mesh filename="Geometry/r_patella.obj" scale="1 1 1" />
      </geometry>
      <material name="patella_r_material_0">
        <color rgba="1 1 1 1" />
      </material>
    </visual>
  </link>
  <joint name="ankle_angle_r" type="revolute">
    <origin xyz="-0.01 0 -0.4" rpy="0.174912588 0 -0.106844366" />
    <parent link="tibia_r" />
    <child link="ankle_angle_r_link" />
    <axis xyz="0 -1 0" />
    <limit effort="1000" velocity="10" lower="-0.6981317" upper="0.52359878" />
  </joint>
  <link name="ankle_angle_r_link">
    <inertial>
      <origin xyz="0 0 0" rpy="0 0 0" />
      <mass value="0.001" />
      <inertia ixx="1e-06" ixy="0" ixz="0" iyy="1e-06" iyz="0" izz="1e-06" />
    </inertial>
  </link>
  <joint name="talus_r_fixed" type="fixed">
    <origin xyz="0 0 0" rpy="-0.173935213 0.0185589863 0.105226208" />
    <parent link="ankle_angle_r_link" />
    <child link="talus_r" />
  </joint>
  <link name="talus_r">
    <inertial>
      <origin xyz="0 0 0" rpy="0 0 0" />
      <mass value="0.1" />
      <inertia ixx="0.001" ixy="0" ixz="0" iyy="0.001" iyz="0" izz="0.001" />
    </inertial>
    <visual name="talus_r_visual_0">
      <origin xyz="0 0 0" rpy="1.57079633 0 0" />
      <geometry>
        <mesh filename="Geometry/r_talus.obj" scale="1 1 1" />
      </geometry>
      <material name="talus_r_material_0">
        <color rgba="1 1 1 1" />
      </material>
    </visual>
  </link>
  <joint name="subtalar_angle_r" type="revolute">
    <origin xyz="-0.04877 -0.00792 -0.04195" rpy="-0.649448181 0 1.72325253" />
    <parent link="talus_r" />
    <child link="subtalar_angle_r_link" />
    <axis xyz="0 -1 0" />
    <limit effort="1000" velocity="10" lower="-0.34906585" upper="0.34906585" />
  </joint>
  <link name="subtalar_angle_r_link">
    <inertial>
      <origin xyz="0 0 0" rpy="0 0 0" />
      <mass value="0.001" />
      <inertia ixx="1e-06" ixy="0" ixz="0" iyy="1e-06" iyz="0" izz="1e-06" />
    </inertial>
  </link>
  <joint name="calcn_r_fixed" type="fixed">
    <origin xyz="0 0 0" rpy="-0.114810127 0.640669843 -1.76137934" />
    <parent link="subtalar_angle_r_link" />
    <child link="calcn_r" />
  </joint>
  <link name="calcn_r">
    <inertial>
      <origin xyz="0.1 0 0.03" rpy="0 0 0" />
      <mass value="1.25" />
      <inertia ixx="0.0014" ixy="0" ixz="0" iyy="0.0041" iyz="0" izz="0.0039" />
    </inertial>
    <visual name="calcn_r_visual_0">
      <origin xyz="0 0 0" rpy="1.57079633 0 0" />
      <geometry>
        <mesh filename="Geometry/r_foot.obj" scale="1 1 1" />
      </geometry>
      <material name="calcn_r_material_0">
        <color rgba="1 1 1 1" />
      </material>
    </visual>
  </link>
  <joint name="mtp_angle_r" type="revolute">
    <origin xyz="0.1788 -0.00108 -0.002" rpy="-3.14159265 0 -0.619900514" />
    <parent link="calcn_r" />
    <child link="mtp_angle_r_link" />
    <axis xyz="0 -1 0" />
    <limit effort="1000" velocity="10" lower="-0.52359878" upper="0.52359878" />
  </joint>
  <link name="mtp_angle_r_link">
    <inertial>
      <origin xyz="0 0 0" rpy="0 0 0" />
      <mass value="0.001" />
      <inertia ixx="1e-06" ixy="0" ixz="0" iyy="1e-06" iyz="0" izz="1e-06" />
    </inertial>
  </link>
  <joint name="toes_r_fixed" type="fixed">
    <origin xyz="0 0 0" rpy="3.14159265 0 -0.619900514" />
    <parent link="mtp_angle_r_link" />
    <child link="toes_r" />
  </joint>
  <link name="toes_r">
    <inertial>
      <origin xyz="0.0346 0.0175 0.006" rpy="0 0 0" />
      <mass value="0.2166" />
      <inertia ixx="0.0001" ixy="0" ixz="0" iyy="0.001" iyz="0" izz="0.0002" />
    </inertial>
    <visual name="toes_r_visual_0">
      <origin xyz="0 0 0" rpy="1.57079633 0 0" />
      <geometry>
        <mesh filename="Geometry/r_bofoot.obj" scale="1 1 1" />
      </geometry>
      <material name="toes_r_material_0">
        <color rgba="1 1 1 1" />
      </material>
    </visual>
  </link>
  <joint name="hip_flexion_l" type="revolute">
    <origin xyz="-0.056276 0.07726 -0.07849" rpy="0 0 0" />
    <parent link="pelvis" />
    <child link="hip_flexion_l_link" />
    <axis xyz="0 -1 0" />
    <limit effort="1000" velocity="10" lower="-0.52359878" upper="2.0943951" />
  </joint>
  <link name="hip_flexion_l_link">
    <inertial>
      <origin xyz="0 0 0" rpy="0 0 0" />
      <mass value="0.001" />
      <inertia ixx="1e-06" ixy="0" ixz="0" iyy="1e-06" iyz="0" izz="1e-06" />
    </inertial>
  </link>
  <joint name="hip_adduction_l" type="revolute">
    <origin xyz="0 0 0" rpy="0 0 0" />
    <parent link="hip_flexion_l_link" />
    <child link="hip_adduction_l_link" />
    <axis xyz="-1 0 0" />
    <limit effort="1000" velocity="10" lower="-0.87266463" upper="0.52359878" />
  </joint>
  <link name="hip_adduction_l_link">
    <inertial>
      <origin xyz="0 0 0" rpy="0 0 0" />
      <mass value="0.001" />
      <inertia ixx="1e-06" ixy="0" ixz="0" iyy="1e-06" iyz="0" izz="1e-06" />
    </inertial>
  </link>
  <joint name="hip_rotation_l" type="revolute">
    <origin xyz="0 0 0" rpy="0 0 0" />
    <parent link="hip_adduction_l_link" />
    <child link="hip_rotation_l_link" />
    <axis xyz="0 0 -1" />
    <limit effort="1000" velocity="10" lower="-0.6981317" upper="0.6981317" />
  </joint>
  <link name="hip_rotation_l_link">
    <inertial>
      <origin xyz="0 0 0" rpy="0 0 0" />
      <mass value="0.001" />
      <inertia ixx="1e-06" ixy="0" ixz="0" iyy="1e-06" iyz="0" izz="1e-06" />
    </inertial>
  </link>
  <joint name="femur_l_fixed" type="fixed">
    <origin xyz="0 0 0" rpy="0 0 0" />
    <parent link="hip_rotation_l_link" />
    <child link="femur_l" />
  </joint>
  <link name="femur_l">
    <inertial>
      <origin xyz="0 0 -0.17" rpy="0 0 0" />
      <mass value="9.3014" />
      <inertia ixx="0.1339" ixy="0" ixz="0" iyy="0.1412" iyz="0" izz="0.0351" />
    </inertial>
    <visual name="femur_l_visual_0">
      <origin xyz="0 0 0" rpy="1.57079633 0 0" />
      <geometry>
        <mesh filename="Geometry/l_femur.obj" scale="1 1 1" />
      </geometry>
      <material name="femur_l_material_0">
        <color rgba="1 1 1 1" />
      </material>
    </visual>
  </link>
  <joint name="knee_angle_l" type="revolute">
    <origin xyz="-0.00809 -0.00275 -0.40796" rpy="0.124615527 0.07077216 -1.57079633" />
    <parent link="femur_l" />
    <child link="knee_angle_l_link" />
    <axis xyz="-1 0 0" />
    <limit effort="1000" velocity="10" lower="0" upper="2.0944" />
  </joint>
  <link name="knee_angle_l_link">
    <inertial>
      <origin xyz="0 0 0" rpy="0 0 0" />
      <mass value="0.001" />
      <inertia ixx="1e-06" ixy="0" ixz="0" iyy="1e-06" iyz="0" izz="1e-06" />
    </inertial>
  </link>
  <joint name="tibia_l_fixed" type="fixed">
    <origin xyz="-0.0017309799 0.00845201222 0.00238895779" rpy="-0.07077216 0.124615527 1.57079633" />
    <parent link="knee_angle_l_link" />
    <child link="tibia_l" />
  </joint>
  <link name="tibia_l">
    <inertial>
      <origin xyz="0 0 -0.1867" rpy="0 0 0" />
      <mass value="3.7075" />
      <inertia ixx="0.0504" ixy="0" ixz="0" iyy="0.0511" iyz="0" izz="0.0051" />
    </inertial>
    <visual name="tibia_l_visual_0">
      <origin xyz="0 0 0" rpy="1.57079633 0 0" />
      <geometry>
        <mesh filename="Geometry/l_tibia.obj" scale="1 1 1" />
      </geometry>
      <material name="tibia_l_material_0">
        <color rgba="1 1 1 1" />
      </material>
    </visual>
    <visual name="tibia_l_visual_1">
      <origin xyz="0 0 0" rpy="1.57079633 0 0" />
      <geometry>
        <mesh filename="Geometry/l_fibula.obj" scale="1 1 1" />
      </geometry>
      <material name="tibia_l_material_1">
        <color rgba="1 1 1 1" />
      </material>
    </visual>
  </link>
  <joint name="patella_l_fixed" type="fixed">
    <origin xyz="0.0443222442 -0.0134904216 -0.41071" rpy="0 0 0.00113686" />
    <parent link="femur_l" />
    <child link="patella_l" />
  </joint>
  <link name="patella_l">
    <inertial>
      <origin xyz="0.0018 0 0.0264" rpy="0 0 0" />
      <mass value="0.0862" />
      <inertia ixx="2.87e-06" ixy="0" ixz="0" iyy="1.311e-05" iyz="0" izz="1.311e-05" />
    </inertial>
    <visual name="patella_l_visual_0">
      <origin xyz="0 0 0" rpy="1.57079633 0 0" />
      <geometry>
        <mesh filename="Geometry/l_patella.obj" scale="1 1 1" />
      </geometry>
      <material name="patella_l_material_0">
        <color rgba="1 1 1 1" />
      </material>
    </visual>
  </link>
  <joint name="ankle_angle_l" type="revolute">
    <origin xyz="-0.01 0 -0.4" rpy="-0.174912588 0 0.106844366" />
    <parent link="tibia_l" />
    <child link="ankle_angle_l_link" />
    <axis xyz="0 -1 0" />
    <limit effort="1000" velocity="10" lower="-0.6981317" upper="0.52359878" />
  </joint>
  <link name="ankle_angle_l_link">
    <inertial>
      <origin xyz="0 0 0" rpy="0 0 0" />
      <mass value="0.001" />
      <inertia ixx="1e-06" ixy="0" ixz="0" iyy="1e-06" iyz="0" izz="1e-06" />
    </inertial>
  </link>
  <joint name="talus_l_fixed" type="fixed">
    <origin xyz="0 0 0" rpy="0.173935213 0.0185589863 -0.105226208" />
    <parent link="ankle_angle_l_link" />
    <child link="talus_l" />
  </joint>
  <link name="talus_l">
    <inertial>
      <origin xyz="0 0 0" rpy="0 0 0" />
      <mass value="0.1" />
      <inertia ixx="0.001" ixy="0" ixz="0" iyy="0.001" iyz="0" izz="0.001" />
    </inertial>
    <visual name="talus_l_visual_0">
      <origin xyz="0 0 0" rpy="1.57079633 0 0" />
      <geometry>
        <mesh filename="Geometry/l_talus.obj" scale="1 1 1" />
      </geometry>
      <material name="talus_l_material_0">
        <color rgba="1 1 1 1" />
      </material>
    </visual>
  </link>
  <joint name="subtalar_angle_l" type="revolute">
    <origin xyz="-0.04877 0.00792 -0.04195" rpy="0.649448181 0 -1.72325253" />
    <parent link="talus_l" />
    <child link="subtalar_angle_l_link" />
    <axis xyz="0 -1 0" />
    <limit effort="1000" velocity="10" lower="-0.34906585" upper="0.34906585" />
  </joint>
  <link name="subtalar_angle_l_link">
    <inertial>
      <origin xyz="0 0 0" rpy="0 0 0" />
      <mass value="0.001" />
      <inertia ixx="1e-06" ixy="0" ixz="0" iyy="1e-06" iyz="0" izz="1e-06" />
    </inertial>
  </link>
  <joint name="calcn_l_fixed" type="fixed">
    <origin xyz="0 0 0" rpy="0.114810127 0.640669843 1.76137934" />
    <parent link="subtalar_angle_l_link" />
    <child link="calcn_l" />
  </joint>
  <link name="calcn_l">
    <inertial>
      <origin xyz="0.1 0 0.03" rpy="0 0 0" />
      <mass value="1.25" />
      <inertia ixx="0.0014" ixy="0" ixz="0" iyy="0.0041" iyz="0" izz="0.0039" />
    </inertial>
    <visual name="calcn_l_visual_0">
      <origin xyz="0 0 0" rpy="1.57079633 0 0" />
      <geometry>
        <mesh filename="Geometry/l_foot.obj" scale="1 1 1" />
      </geometry>
      <material name="calcn_l_material_0">
        <color rgba="1 1 1 1" />
      </material>
    </visual>
  </link>
  <joint name="mtp_angle_l" type="revolute">
    <origin xyz="0.1788 0.00108 -0.002" rpy="-3.14159265 0 0.619900514" />
    <parent link="calcn_l" />
    <child link="mtp_angle_l_link" />
    <axis xyz="0 -1 0" />
    <limit effort="1000" velocity="10" lower="-0.52359878" upper="0.52359878" />
  </joint>
  <link name="mtp_angle_l_link">
    <inertial>
      <origin xyz="0 0 0" rpy="0 0 0" />
      <mass value="0.001" />
      <inertia ixx="1e-06" ixy="0" ixz="0" iyy="1e-06" iyz="0" izz="1e-06" />
    </inertial>
  </link>
  <joint name="toes_l_fixed" type="fixed">
    <origin xyz="0 0 0" rpy="3.14159265 0 0.619900514" />
    <parent link="mtp_angle_l_link" />
    <child link="toes_l" />
  </joint>
  <link name="toes_l">
    <inertial>
      <origin xyz="0.0346 -0.0175 0.006" rpy="0 0 0" />
      <mass value="0.2166" />
      <inertia ixx="0.0001" ixy="0" ixz="0" iyy="0.001" iyz="0" izz="0.0002" />
    </inertial>
    <visual name="toes_l_visual_0">
      <origin xyz="0 0 0" rpy="1.57079633 0 0" />
      <geometry>
        <mesh filename="Geometry/l_bofoot.obj" scale="1 1 1" />
      </geometry>
      <material name="toes_l_material_0">
        <color rgba="1 1 1 1" />
      </material>
    </visual>
  </link>
  <joint name="lumbar_extension" type="revolute">
    <origin xyz="-0.1007 0 0.0815" rpy="0 0 0" />
    <parent link="pelvis" />
    <child link="lumbar_extension_link" />
    <axis xyz="0 -1 0" />
    <limit effort="1000" velocity="10" lower="-1.57079633" upper="1.57079633" />
  </joint>
  <link name="lumbar_extension_link">
    <inertial>
      <origin xyz="0 0 0" rpy="0 0 0" />
      <mass value="0.001" />
      <inertia ixx="1e-06" ixy="0" ixz="0" iyy="1e-06" iyz="0" izz="1e-06" />
    </inertial>
  </link>
  <joint name="lumbar_bending" type="revolute">
    <origin xyz="0 0 0" rpy="0 0 0" />
    <parent link="lumbar_extension_link" />
    <child link="lumbar_bending_link" />
    <axis xyz="1 0 0" />
    <limit effort="1000" velocity="10" lower="-1.57079633" upper="1.57079633" />
  </joint>
  <link name="lumbar_bending_link">
    <inertial>
      <origin xyz="0 0 0" rpy="0 0 0" />
      <mass value="0.001" />
      <inertia ixx="1e-06" ixy="0" ixz="0" iyy="1e-06" iyz="0" izz="1e-06" />
    </inertial>
  </link>
  <joint name="lumbar_rotation" type="revolute">
    <origin xyz="0 0 0" rpy="0 0 0" />
    <parent link="lumbar_bending_link" />
    <child link="lumbar_rotation_link" />
    <axis xyz="0 0 1" />
    <limit effort="1000" velocity="10" lower="-1.57079633" upper="1.57079633" />
  </joint>
  <link name="lumbar_rotation_link">
    <inertial>
      <origin xyz="0 0 0" rpy="0 0 0" />
      <mass value="0.001" />
      <inertia ixx="1e-06" ixy="0" ixz="0" iyy="1e-06" iyz="0" izz="1e-06" />
    </inertial>
  </link>
  <joint name="torso_fixed" type="fixed">
    <origin xyz="0 0 0" rpy="0 0 0" />
    <parent link="lumbar_rotation_link" />
    <child link="torso" />
  </joint>
  <link name="torso">
    <inertial>
      <origin xyz="-0.03 0 0.32" rpy="0 0 0" />
      <mass value="26.8266" />
      <inertia ixx="1.4745" ixy="0" ixz="0" iyy="1.4314" iyz="0" izz="0.7555" />
    </inertial>
    <visual name="torso_visual_0">
      <origin xyz="0 0 0" rpy="1.57079633 0 0" />
      <geometry>
        <mesh filename="Geometry/hat_spine.obj" scale="1 1 1" />
      </geometry>
      <material name="torso_material_0">
        <color rgba="1 1 1 1" />
      </material>
    </visual>
    <visual name="torso_visual_1">
      <origin xyz="0 0 0" rpy="1.57079633 0 0" />
      <geometry>
        <mesh filename="Geometry/hat_jaw.obj" scale="1 1 1" />
      </geometry>
      <material name="torso_material_1">
        <color rgba="1 1 1 1" />
      </material>
    </visual>
    <visual name="torso_visual_2">
      <origin xyz="0 0 0" rpy="1.57079633 0 0" />
      <geometry>
        <mesh filename="Geometry/hat_skull.obj" scale="1 1 1" />
      </geometry>
      <material name="torso_material_2">
        <color rgba="1 1 1 1" />
      </material>
    </visual>
    <visual name="torso_visual_3">
      <origin xyz="0 0 0" rpy="1.57079633 0 0" />
      <geometry>
        <mesh filename="Geometry/hat_ribs_scap.obj" scale="1 1 1" />
      </geometry>
      <material name="torso_material_3">
        <color rgba="1 1 1 1" />
      </material>
    </visual>
  </link>
  <joint name="arm_flex_r" type="revolute">
    <origin xyz="0.003155 -0.17 0.3715" rpy="0 0 0" />
    <parent link="torso" />
    <child link="arm_flex_r_link" />
    <axis xyz="0 -1 0" />
    <limit effort="1000" velocity="10" lower="-1.57079633" upper="1.57079633" />
  </joint>
  <link name="arm_flex_r_link">
    <inertial>
      <origin xyz="0 0 0" rpy="0 0 0" />
      <mass value="0.001" />
      <inertia ixx="1e-06" ixy="0" ixz="0" iyy="1e-06" iyz="0" izz="1e-06" />
    </inertial>
  </link>
  <joint name="arm_add_r" type="revolute">
    <origin xyz="0 0 0" rpy="0 0 0" />
    <parent link="arm_flex_r_link" />
    <child link="arm_add_r_link" />
    <axis xyz="1 0 0" />
    <limit effort="1000" velocity="10" lower="-2.0943951" upper="1.57079633" />
  </joint>
  <link name="arm_add_r_link">
    <inertial>
      <origin xyz="0 0 0" rpy="0 0 0" />
      <mass value="0.001" />
      <inertia ixx="1e-06" ixy="0" ixz="0" iyy="1e-06" iyz="0" izz="1e-06" />
    </inertial>
  </link>
  <joint name="arm_rot_r" type="revolute">
    <origin xyz="0 0 0" rpy="0 0 0" />
    <parent link="arm_add_r_link" />
    <child link="arm_rot_r_link" />
    <axis xyz="0 0 1" />
    <limit effort="1000" velocity="10" lower="-1.57079633" upper="1.57079633" />
  </joint>
  <link name="arm_rot_r_link">
    <inertial>
      <origin xyz="0 0 0" rpy="0 0 0" />
      <mass value="0.001" />
      <inertia ixx="1e-06" ixy="0" ixz="0" iyy="1e-06" iyz="0" izz="1e-06" />
    </inertial>
  </link>
  <joint name="humerus_r_fixed" type="fixed">
    <origin xyz="0 0 0" rpy="0 0 0" />
    <parent link="arm_rot_r_link" />
    <child link="humerus_r" />
  </joint>
  <link name="humerus_r">
    <inertial>
      <origin xyz="0 0 -0.164502" rpy="0 0 0" />
      <mass value="2.0325" />
      <inertia ixx="0.011946" ixy="0" ixz="0" iyy="0.013409" iyz="0" izz="0.004121" />
    </inertial>
    <visual name="humerus_r_visual_0">
      <origin xyz="0 0 0" rpy="1.57079633 0 0" />
      <geometry>
        <mesh filename="Geometry/humerus_rv.obj" scale="1 1 1" />
      </geometry>
      <material name="humerus_r_material_0">
        <color rgba="1 1 1 1" />
      </material>
    </visual>
  </link>
  <joint name="elbow_flex_r" type="revolute">
    <origin xyz="0.013144 0.009595 -0.286273" rpy="-0.022270841 0 0.228075242" />
    <parent link="humerus_r" />
    <child link="elbow_flex_r_link" />
    <axis xyz="0 -1 0" />
    <limit effort="1000" velocity="10" lower="0" upper="2.618" />
  </joint>
  <link name="elbow_flex_r_link">
    <inertial>
      <origin xyz="0 0 0" rpy="0 0 0" />
      <mass value="0.001" />
      <inertia ixx="1e-06" ixy="0" ixz="0" iyy="1e-06" iyz="0" izz="1e-06" />
    </inertial>
  </link>
  <joint name="ulna_r_fixed" type="fixed">
    <origin xyz="0 0 0" rpy="0.0216942851 0.00503510965 -0.228020623" />
    <parent link="elbow_flex_r_link" />
    <child link="ulna_r" />
  </joint>
  <link name="ulna_r">
    <inertial>
      <origin xyz="0 0 -0.120525" rpy="0 0 0" />
      <mass value="0.6075" />
      <inertia ixx="0.002962" ixy="0" ixz="0" iyy="0.003213" iyz="0" izz="0.000618" />
    </inertial>
    <visual name="ulna_r_visual_0">
      <origin xyz="0 0 0" rpy="1.57079633 0 0" />
      <geometry>
        <mesh filename="Geometry/ulna_rv.obj" scale="1 1 1" />
      </geometry>
      <material name="ulna_r_material_0">
        <color rgba="1 1 1 1" />
      </material>
    </visual>
  </link>
  <joint name="pro_sup_r" type="revolute">
    <origin xyz="-0.006727 -0.026083 -0.013007" rpy="-1.51433453 0 1.536199" />
    <parent link="ulna_r" />
    <child link="pro_sup_r_link" />
    <axis xyz="0 -1 0" />
    <limit effort="1000" velocity="10" lower="0" upper="1.57079633" />
  </joint>
  <link name="pro_sup_r_link">
    <inertial>
      <origin xyz="0 0 0" rpy="0 0 0" />
      <mass value="0.001" />
      <inertia ixx="1e-06" ixy="0" ixz="0" iyy="1e-06" iyz="0" izz="1e-06" />
    </inertial>
  </link>
  <joint name="radius_r_fixed" type="fixed">
    <origin xyz="0 0 0" rpy="0.549183996 1.50458729 -1.02063526" />
    <parent link="pro_sup_r_link" />
    <child link="radius_r" />
  </joint>
  <link name="radius_r">
    <inertial>
      <origin xyz="0 0 -0.120525" rpy="0 0 0" />
      <mass value="0.6075" />
      <inertia ixx="0.002962" ixy="0" ixz="0" iyy="0.003213" iyz="0" izz="0.000618" />
    </inertial>
    <visual name="radius_r_visual_0">
      <origin xyz="0 0 0" rpy="1.57079633 0 0" />
      <geometry>
        <mesh filename="Geometry/radius_rv.obj" scale="1 1 1" />
      </geometry>
      <material name="radius_r_material_0">
        <color rgba="1 1 1 1" />
      </material>
    </visual>
  </link>
  <joint name="wrist_flex_r" type="revolute">
    <origin xyz="-0.008797 -0.01361 -0.235841" rpy="-1.57079633 0 -1.57079633" />
    <parent link="radius_r" />
    <child link="wrist_flex_r_link" />
    <axis xyz="1 0 0" />
    <limit effort="1000" velocity="10" lower="-1.22173048" upper="1.22173048" />
  </joint>
  <link name="wrist_flex_r_link">
    <inertial>
      <origin xyz="0 0 0" rpy="0 0 0" />
      <mass value="0.001" />
      <inertia ixx="1e-06" ixy="0" ixz="0" iyy="1e-06" iyz="0" izz="1e-06" />
    </inertial>
  </link>
  <joint name="wrist_dev_r" type="revolute">
    <origin xyz="0 0 0" rpy="0 0 0" />
    <parent link="wrist_flex_r_link" />
    <child link="wrist_dev_r_link" />
    <axis xyz="0 0 1" />
    <limit effort="1000" velocity="10" lower="-0.43633231" upper="0.61086524" />
  </joint>
  <link name="wrist_dev_r_link">
    <inertial>
      <origin xyz="0 0 0" rpy="0 0 0" />
      <mass value="0.001" />
      <inertia ixx="1e-06" ixy="0" ixz="0" iyy="1e-06" iyz="0" izz="1e-06" />
    </inertial>
  </link>
  <joint name="hand_r_fixed" type="fixed">
    <origin xyz="0 0 0" rpy="1.57079633 -1.57079633 0" />
    <parent link="wrist_dev_r_link" />
    <child link="hand_r" />
  </joint>
  <link name="hand_r">
    <inertial>
      <origin xyz="0 0 -0.068095" rpy="0 0 0" />
      <mass value="0.4575" />
      <inertia ixx="0.000892" ixy="0" ixz="0" iyy="0.00134" iyz="0" izz="0.000547" />
    </inertial>
    <visual name="hand_r_visual_0">
      <origin xyz="0 0 0" rpy="1.57079633 0 0" />
      <geometry>
        <mesh filename="Geometry/pisiform_rvs.obj" scale="0.85 0.85 0.85" />
      </geometry>
      <material name="hand_r_material_0">
        <color rgba="1 1 1 1" />
      </material>
    </visual>
    <visual name="hand_r_visual_1">
      <origin xyz="0 0 0" rpy="1.57079633 0 0" />
      <geometry>
        <mesh filename="Geometry/lunate_rvs.obj" scale="0.85 0.85 0.85" />
      </geometry>
      <material name="hand_r_material_1">
        <color rgba="1 1 1 1" />
      </material>
    </visual>
    <visual name="hand_r_visual_2">
      <origin xyz="0 0 0" rpy="1.57079633 0 0" />
      <geometry>
        <mesh filename="Geometry/scaphoid_rvs.obj" scale="0.85 0.85 0.85" />
      </geometry>
      <material name="hand_r_material_2">
        <color rgba="1 1 1 1" />
      </material>
    </visual>
    <visual name="hand_r_visual_3">
      <origin xyz="0 0 0" rpy="1.57079633 0 0" />
      <geometry>
        <mesh filename="Geometry/triquetrum_rvs.obj" scale="0.85 0.85 0.85" />
      </geometry>
      <material name="hand_r_material_3">
        <color rgba="1 1 1 1" />
      </material>
    </visual>
    <visual name="hand_r_visual_4">
      <origin xyz="0 0 0" rpy="1.57079633 0 0" />
      <geometry>
        <mesh filename="Geometry/hamate_rvs.obj" scale="0.85 0.85 0.85" />
      </geometry>
      <material name="hand_r_material_4">
        <color rgba="1 1 1 1" />
      </material>
    </visual>
    <visual name="hand_r_visual_5">
      <origin xyz="0 0 0" rpy="1.57079633 0 0" />
      <geometry>
        <mesh filename="Geometry/capitate_rvs.obj" scale="0.85 0.85 0.85" />
      </geometry>
      <material name="hand_r_material_5">
        <color rgba="1 1 1 1" />
      </material>
    </visual>
    <visual name="hand_r_visual_6">
      <origin xyz="0 0 0" rpy="1.57079633 0 0" />
      <geometry>
        <mesh filename="Geometry/trapezoid_rvs.obj" scale="0.85 0.85 0.85" />
      </geometry>
      <material name="hand_r_material_6">
        <color rgba="1 1 1 1" />
      </material>
    </visual>
    <visual name="hand_r_visual_7">
      <origin xyz="0 0 0" rpy="1.57079633 0 0" />
      <geometry>
        <mesh filename="Geometry/trapezium_rvs.obj" scale="0.85 0.85 0.85" />
      </geometry>
      <material name="hand_r_material_7">
        <color rgba="1 1 1 1" />
      </material>
    </visual>
    <visual name="hand_r_visual_8">
      <origin xyz="0 0 0" rpy="1.57079633 0 0" />
      <geometry>
        <mesh filename="Geometry/metacarpal2_rvs.obj" scale="0.85 0.85 0.85" />
      </geometry>
      <material name="hand_r_material_8">
        <color rgba="1 1 1 1" />
      </material>
    </visual>
    <visual name="hand_r_visual_9">
      <origin xyz="0 0 0" rpy="1.57079633 0 0" />
      <geometry>
        <mesh filename="Geometry/index_proximal_rvs.obj" scale="0.85 0.85 0.85" />
      </geometry>
      <material name="hand_r_material_9">
        <color rgba="1 1 1 1" />
      </material>
    </visual>
    <visual name="hand_r_visual_10">
      <origin xyz="0 0 0" rpy="1.57079633 0 0" />
      <geometry>
        <mesh filename="Geometry/index_medial_rvs.obj" scale="0.85 0.85 0.85" />
      </geometry>
      <material name="hand_r_material_10">
        <color rgba="1 1 1 1" />
      </material>
    </visual>
    <visual name="hand_r_visual_11">
      <origin xyz="0 0 0" rpy="1.57079633 0 0" />
      <geometry>
        <mesh filename="Geometry/index_distal_rvs.obj" scale="0.85 0.85 0.85" />
      </geometry>
      <material name="hand_r_material_11">
        <color rgba="1 1 1 1" />
      </material>
    </visual>
    <visual name="hand_r_visual_12">
      <origin xyz="0 0 0" rpy="1.57079633 0 0" />
      <geometry>
        <mesh filename="Geometry/metacarpal3_rvs.obj" scale="0.85 0.85 0.85" />
      </geometry>
      <material name="hand_r_material_12">
        <color rgba="1 1 1 1" />
      </material>
    </visual>
    <visual name="hand_r_visual_13">
      <origin xyz="0 0 0" rpy="1.57079633 0 0" />
      <geometry>
        <mesh filename="Geometry/middle_proximal_rvs.obj" scale="0.85 0.85 0.85" />
      </geometry>
      <material name="hand_r_material_13">
        <color rgba="1 1 1 1" />
      </material>
    </visual>
    <visual name="hand_r_visual_14">
      <origin xyz="0 0 0" rpy="1.57079633 0 0" />
      <geometry>
        <mesh filename="Geometry/middle_medial_rvs.obj" scale="0.85 0.85 0.85" />
      </geometry>
      <material name="hand_r_material_14">
        <color rgba="1 1 1 1" />
      </material>
    </visual>
    <visual name="hand_r_visual_15">
      <origin xyz="0 0 0" rpy="1.57079633 0 0" />
      <geometry>
        <mesh filename="Geometry/middle_distal_rvs.obj" scale="0.85 0.85 0.85" />
      </geometry>
      <material name="hand_r_material_15">
        <color rgba="1 1 1 1" />
      </material>
    </visual>
    <visual name="hand_r_visual_16">
      <origin xyz="0 0 0" rpy="1.57079633 0 0" />
      <geometry>
        <mesh filename="Geometry/metacarpal4_rvs.obj" scale="0.85 0.85 0.85" />
      </geometry>
      <material name="hand_r_material_16">
        <color rgba="1 1 1 1" />
      </material>
    </visual>
    <visual name="hand_r_visual_17">
      <origin xyz="0 0 0" rpy="1.57079633 0 0" />
      <geometry>
        <mesh filename="Geometry/ring_proximal_rvs.obj" scale="0.85 0.85 0.85" />
      </geometry>
      <material name="hand_r_material_17">
        <color rgba="1 1 1 1" />
      </material>
    </visual>
    <visual name="hand_r_visual_18">
      <origin xyz="0 0 0" rpy="1.57079633 0 0" />
      <geometry>
        <mesh filename="Geometry/ring_medial_rvs.obj" scale="0.85 0.85 0.85" />
      </geometry>
      <material name="hand_r_material_18">
        <color rgba="1 1 1 1" />
      </material>
    </visual>
    <visual name="hand_r_visual_19">
      <origin xyz="0 0 0" rpy="1.57079633 0 0" />
      <geometry>
        <mesh filename="Geometry/ring_distal_rvs.obj" scale="0.85 0.85 0.85" />
      </geometry>
      <material name="hand_r_material_19">
        <color rgba="1 1 1 1" />
      </material>
    </visual>
    <visual name="hand_r_visual_20">
      <origin xyz="0 0 0" rpy="1.57079633 0 0" />
      <geometry>
        <mesh filename="Geometry/metacarpal5_rvs.obj" scale="0.85 0.85 0.85" />
      </geometry>
      <material name="hand_r_material_20">
        <color rgba="1 1 1 1" />
      </material>
    </visual>
    <visual name="hand_r_visual_21">
      <origin xyz="0 0 0" rpy="1.57079633 0 0" />
      <geometry>
        <mesh filename="Geometry/little_proximal_rvs.obj" scale="0.85 0.85 0.85" />
      </geometry>
      <material name="hand_r_material_21">
        <color rgba="1 1 1 1" />
      </material>
    </visual>
    <visual name="hand_r_visual_22">
      <origin xyz="0 0 0" rpy="1.57079633 0 0" />
      <geometry>
        <mesh filename="Geometry/little_medial_rvs.obj" scale="0.85 0.85 0.85" />
      </geometry>
      <material name="hand_r_material_22">
        <color rgba="1 1 1 1" />
      </material>
    </visual>
    <visual name="hand_r_visual_23">
      <origin xyz="0 0 0" rpy="1.57079633 0 0" />
      <geometry>
        <mesh filename="Geometry/little_distal_rvs.obj" scale="0.85 0.85 0.85" />
      </geometry>
      <material name="hand_r_material_23">
        <color rgba="1 1 1 1" />
      </material>
    </visual>
    <visual name="hand_r_visual_24">
      <origin xyz="0 0 0" rpy="1.57079633 0 0" />
      <geometry>
        <mesh filename="Geometry/metacarpal1_rvs.obj" scale="0.85 0.85 0.85" />
      </geometry>
      <material name="hand_r_material_24">
        <color rgba="1 1 1 1" />
      </material>
    </visual>
    <visual name="hand_r_visual_25">
      <origin xyz="0 0 0" rpy="1.57079633 0 0" />
      <geometry>
        <mesh filename="Geometry/thumb_proximal_rvs.obj" scale="0.85 0.85 0.85" />
      </geometry>
      <material name="hand_r_material_25">
        <color rgba="1 1 1 1" />
      </material>
    </visual>
    <visual name="hand_r_visual_26">
      <origin xyz="0 0 0" rpy="1.57079633 0 0" />
      <geometry>
        <mesh filename="Geometry/thumb_distal_rvs.obj" scale="0.85 0.85 0.85" />
      </geometry>
      <material name="hand_r_material_26">
        <color rgba="1 1 1 1" />
      </material>
    </visual>
  </link>
  <joint name="arm_flex_l" type="revolute">
    <origin xyz="0.003155 0.17 0.3715" rpy="0 0 0" />
    <parent link="torso" />
    <child link="arm_flex_l_link" />
    <axis xyz="0 -1 0" />
    <limit effort="1000" velocity="10" lower="-1.57079633" upper="1.57079633" />
  </joint>
  <link name="arm_flex_l_link">
    <inertial>
      <origin xyz="0 0 0" rpy="0 0 0" />
      <mass value="0.001" />
      <inertia ixx="1e-06" ixy="0" ixz="0" iyy="1e-06" iyz="0" izz="1e-06" />
    </inertial>
  </link>
  <joint name="arm_add_l" type="revolute">
    <origin xyz="0 0 0" rpy="0 0 0" />
    <parent link="arm_flex_l_link" />
    <child link="arm_add_l_link" />
    <axis xyz="-1 0 0" />
    <limit effort="1000" velocity="10" lower="-2.0943951" upper="1.57079633" />
  </joint>
  <link name="arm_add_l_link">
    <inertial>
      <origin xyz="0 0 0" rpy="0 0 0" />
      <mass value="0.001" />
      <inertia ixx="1e-06" ixy="0" ixz="0" iyy="1e-06" iyz="0" izz="1e-06" />
    </inertial>
  </link>
  <joint name="arm_rot_l" type="revolute">
    <origin xyz="0 0 0" rpy="0 0 0" />
    <parent link="arm_add_l_link" />
    <child link="arm_rot_l_link" />
    <axis xyz="0 0 -1" />
    <limit effort="1000" velocity="10" lower="-1.57079633" upper="1.57079633" />
  </joint>
  <link name="arm_rot_l_link">
    <inertial>
      <origin xyz="0 0 0" rpy="0 0 0" />
      <mass value="0.001" />
      <inertia ixx="1e-06" ixy="0" ixz="0" iyy="1e-06" iyz="0" izz="1e-06" />
    </inertial>
  </link>
  <joint name="humerus_l_fixed" type="fixed">
    <origin xyz="0 0 0" rpy="0 0 0" />
    <parent link="arm_rot_l_link" />
    <child link="humerus_l" />
  </joint>
  <link name="humerus_l">
    <inertial>
      <origin xyz="0 0 -0.164502" rpy="0 0 0" />
      <mass value="2.0325" />
      <inertia ixx="0.011946" ixy="0" ixz="0" iyy="0.013409" iyz="0" izz="0.004121" />
    </inertial>
    <visual name="humerus_l_visual_0">
      <origin xyz="0 0 0" rpy="1.57079633 0 0" />
      <geometry>
        <mesh filename="Geometry/humerus_lv.obj" scale="1 1 1" />
      </geometry>
      <material name="humerus_l_material_0">
        <color rgba="1 1 1 1" />
      </material>
    </visual>
  </link>
  <joint name="elbow_flex_l" type="revolute">
    <origin xyz="0.013144 -0.009595 -0.286273" rpy="0.022270841 0 -0.228075242" />
    <parent link="humerus_l" />
    <child link="elbow_flex_l_link" />
    <axis xyz="0 -1 0" />
    <limit effort="1000" velocity="10" lower="0" upper="2.618" />
  </joint>
  <link name="elbow_flex_l_link">
    <inertial>
      <origin xyz="0 0 0" rpy="0 0 0" />
      <mass value="0.001" />
      <inertia ixx="1e-06" ixy="0" ixz="0" iyy="1e-06" iyz="0" izz="1e-06" />
    </inertial>
  </link>
  <joint name="ulna_l_fixed" type="fixed">
    <origin xyz="0 0 0" rpy="-0.0216942851 0.00503510965 0.228020623" />
    <parent link="elbow_flex_l_link" />
    <child link="ulna_l" />
  </joint>
  <link name="ulna_l">
    <inertial>
      <origin xyz="0 0 -0.120525" rpy="0 0 0" />
      <mass value="0.6075" />
      <inertia ixx="0.002962" ixy="0" ixz="0" iyy="0.003213" iyz="0" izz="0.000618" />
    </inertial>
    <visual name="ulna_l_visual_0">
      <origin xyz="0 0 0" rpy="1.57079633 0 0" />
      <geometry>
        <mesh filename="Geometry/ulna_lv.obj" scale="1 1 1" />
      </geometry>
      <material name="ulna_l_material_0">
        <color rgba="1 1 1 1" />
      </material>
    </visual>
  </link>
  <joint name="pro_sup_l" type="revolute">
    <origin xyz="-0.006727 0.026083 -0.013007" rpy="1.51433453 0 -1.536199" />
    <parent link="ulna_l" />
    <child link="pro_sup_l_link" />
    <axis xyz="0 -1 0" />
    <limit effort="1000" velocity="10" lower="0" upper="1.57079633" />
  </joint>
  <link name="pro_sup_l_link">
    <inertial>
      <origin xyz="0 0 0" rpy="0 0 0" />
      <mass value="0.001" />
      <inertia ixx="1e-06" ixy="0" ixz="0" iyy="1e-06" iyz="0" izz="1e-06" />
    </inertial>
  </link>
  <joint name="radius_l_fixed" type="fixed">
    <origin xyz="0 0 0" rpy="-0.549183996 1.50458729 1.02063526" />
    <parent link="pro_sup_l_link" />
    <child link="radius_l" />
  </joint>
  <link name="radius_l">
    <inertial>
      <origin xyz="0 0 -0.120525" rpy="0 0 0" />
      <mass value="0.6075" />
      <inertia ixx="0.002962" ixy="0" ixz="0" iyy="0.003213" iyz="0" izz="0.000618" />
    </inertial>
    <visual name="radius_l_visual_0">
      <origin xyz="0 0 0" rpy="1.57079633 0 0" />
      <geometry>
        <mesh filename="Geometry/radius_lv.obj" scale="1 1 1" />
      </geometry>
      <material name="radius_l_material_0">
        <color rgba="1 1 1 1" />
      </material>
    </visual>
  </link>
  <joint name="wrist_flex_l" type="revolute">
    <origin xyz="-0.008797 0.01361 -0.235841" rpy="1.57079633 0 -1.57079633" />
    <parent link="radius_l" />
    <child link="wrist_flex_l_link" />
    <axis xyz="1 0 0" />
    <limit effort="1000" velocity="10" lower="-1.22173048" upper="1.22173048" />
  </joint>
  <link name="wrist_flex_l_link">
    <inertial>
      <origin xyz="0 0 0" rpy="0 0 0" />
      <mass value="0.001" />
      <inertia ixx="1e-06" ixy="0" ixz="0" iyy="1e-06" iyz="0" izz="1e-06" />
    </inertial>
  </link>
  <joint name="wrist_dev_l" type="revolute">
    <origin xyz="0 0 0" rpy="0 0 0" />
    <parent link="wrist_flex_l_link" />
    <child link="wrist_dev_l_link" />
    <axis xyz="0 0 1" />
    <limit effort="1000" velocity="10" lower="-0.43633231" upper="0.61086524" />
  </joint>
  <link name="wrist_dev_l_link">
    <inertial>
      <origin xyz="0 0 0" rpy="0 0 0" />
      <mass value="0.001" />
      <inertia ixx="1e-06" ixy="0" ixz="0" iyy="1e-06" iyz="0" izz="1e-06" />
    </inertial>
  </link>
  <joint name="hand_l_fixed" type="fixed">
    <origin xyz="0 0 0" rpy="-1.57079633 1.57079633 0" />
    <parent link="wrist_dev_l_link" />
    <child link="hand_l" />
  </joint>
  <link name="hand_l">
    <inertial>
      <origin xyz="0 0 -0.068095" rpy="0 0 0" />
      <mass value="0.4575" />
      <inertia ixx="0.000892" ixy="0" ixz="0" iyy="0.00134" iyz="0" izz="0.000547" />
    </inertial>
    <visual name="hand_l_visual_0">
      <origin xyz="0 0 0" rpy="1.57079633 0 0" />
      <geometry>
        <mesh filename="Geometry/pisiform_lvs.obj" scale="0.85 0.85 0.85" />
      </geometry>
      <material name="hand_l_material_0">
        <color rgba="1 1 1 1" />
      </material>
    </visual>
    <visual name="hand_l_visual_1">
      <origin xyz="0 0 0" rpy="1.57079633 0 0" />
      <geometry>
        <mesh filename="Geometry/lunate_lvs.obj" scale="0.85 0.85 0.85" />
      </geometry>
      <material name="hand_l_material_1">
        <color rgba="1 1 1 1" />
      </material>
    </visual>
    <visual name="hand_l_visual_2">
      <origin xyz="0 0 0" rpy="1.57079633 0 0" />
      <geometry>
        <mesh filename="Geometry/scaphoid_lvs.obj" scale="0.85 0.85 0.85" />
      </geometry>
      <material name="hand_l_material_2">
        <color rgba="1 1 1 1" />
      </material>
    </visual>
    <visual name="hand_l_visual_3">
      <origin xyz="0 0 0" rpy="1.57079633 0 0" />
      <geometry>
        <mesh filename="Geometry/triquetrum_lvs.obj" scale="0.85 0.85 0.85" />
      </geometry>
      <material name="hand_l_material_3">
        <color rgba="1 1 1 1" />
      </material>
    </visual>
    <visual name="hand_l_visual_4">
      <origin xyz="0 0 0" rpy="1.57079633 0 0" />
      <geometry>
        <mesh filename="Geometry/hamate_lvs.obj" scale="0.85 0.85 0.85" />
      </geometry>
      <material name="hand_l_material_4">
        <color rgba="1 1 1 1" />
      </material>
    </visual>
    <visual name="hand_l_visual_5">
      <origin xyz="0 0 0" rpy="1.57079633 0 0" />
      <geometry>
        <mesh filename="Geometry/capitate_lvs.obj" scale="0.85 0.85 0.85" />
      </geometry>
      <material name="hand_l_material_5">
        <color rgba="1 1 1 1" />
      </material>
    </visual>
    <visual name="hand_l_visual_6">
      <origin xyz="0 0 0" rpy="1.57079633 0 0" />
      <geometry>
        <mesh filename="Geometry/trapezoid_lvs.obj" scale="0.85 0.85 0.85" />
      </geometry>
      <material name="hand_l_material_6">
        <color rgba="1 1 1 1" />
      </material>
    </visual>
    <visual name="hand_l_visual_7">
      <origin xyz="0 0 0" rpy="1.57079633 0 0" />
      <geometry>
        <mesh filename="Geometry/trapezium_lvs.obj" scale="0.85 0.85 0.85" />
      </geometry>
      <material name="hand_l_material_7">
        <color rgba="1 1 1 1" />
      </material>
    </visual>
    <visual name="hand_l_visual_8">
      <origin xyz="0 0 0" rpy="1.57079633 0 0" />
      <geometry>
        <mesh filename="Geometry/metacarpal2_lvs.obj" scale="0.85 0.85 0.85" />
      </geometry>
      <material name="hand_l_material_8">
        <color rgba="1 1 1 1" />
      </material>
    </visual>
    <visual name="hand_l_visual_9">
      <origin xyz="0 0 0" rpy="1.57079633 0 0" />
      <geometry>
        <mesh filename="Geometry/index_proximal_lvs.obj" scale="0.85 0.85 0.85" />
      </geometry>
      <material name="hand_l_material_9">
        <color rgba="1 1 1 1" />
      </material>
    </visual>
    <visual name="hand_l_visual_10">
      <origin xyz="0 0 0" rpy="1.57079633 0 0" />
      <geometry>
        <mesh filename="Geometry/index_medial_lvs.obj" scale="0.85 0.85 0.85" />
      </geometry>
      <material name="hand_l_material_10">
        <color rgba="1 1 1 1" />
      </material>
    </visual>
    <visual name="hand_l_visual_11">
      <origin xyz="0 0 0" rpy="1.57079633 0 0" />
      <geometry>
        <mesh filename="Geometry/index_distal_lvs.obj" scale="0.85 0.85 0.85" />
      </geometry>
      <material name="hand_l_material_11">
        <color rgba="1 1 1 1" />
      </material>
    </visual>
    <visual name="hand_l_visual_12">
      <origin xyz="0 0 0" rpy="1.57079633 0 0" />
      <geometry>
        <mesh filename="Geometry/metacarpal3_lvs.obj" scale="0.85 0.85 0.85" />
      </geometry>
      <material name="hand_l_material_12">
        <color rgba="1 1 1 1" />
      </material>
    </visual>
    <visual name="hand_l_visual_13">
      <origin xyz="0 0 0" rpy="1.57079633 0 0" />
      <geometry>
        <mesh filename="Geometry/middle_proximal_lvs.obj" scale="0.85 0.85 0.85" />
      </geometry>
      <material name="hand_l_material_13">
        <color rgba="1 1 1 1" />
      </material>
    </visual>
    <visual name="hand_l_visual_14">
      <origin xyz="0 0 0" rpy="1.57079633 0 0" />
      <geometry>
        <mesh filename="Geometry/middle_medial_lvs.obj" scale="0.85 0.85 0.85" />
      </geometry>
      <material name="hand_l_material_14">
        <color rgba="1 1 1 1" />
      </material>
    </visual>
    <visual name="hand_l_visual_15">
      <origin xyz="0 0 0" rpy="1.57079633 0 0" />
      <geometry>
        <mesh filename="Geometry/middle_distal_lvs.obj" scale="0.85 0.85 0.85" />
      </geometry>
      <material name="hand_l_material_15">
        <color rgba="1 1 1 1" />
      </material>
    </visual>
    <visual name="hand_l_visual_16">
      <origin xyz="0 0 0" rpy="1.57079633 0 0" />
      <geometry>
        <mesh filename="Geometry/metacarpal4_lvs.obj" scale="0.85 0.85 0.85" />
      </geometry>
      <material name="hand_l_material_16">
        <color rgba="1 1 1 1" />
      </material>
    </visual>
    <visual name="hand_l_visual_17">
      <origin xyz="0 0 0" rpy="1.57079633 0 0" />
      <geometry>
        <mesh filename="Geometry/ring_proximal_lvs.obj" scale="0.85 0.85 0.85" />
      </geometry>
      <material name="hand_l_material_17">
        <color rgba="1 1 1 1" />
      </material>
    </visual>
    <visual name="hand_l_visual_18">
      <origin xyz="0 0 0" rpy="1.57079633 0 0" />
      <geometry>
        <mesh filename="Geometry/ring_medial_lvs.obj" scale="0.85 0.85 0.85" />
      </geometry>
      <material name="hand_l_material_18">
        <color rgba="1 1 1 1" />
      </material>
    </visual>
    <visual name="hand_l_visual_19">
      <origin xyz="0 0 0" rpy="1.57079633 0 0" />
      <geometry>
        <mesh filename="Geometry/ring_distal_lvs.obj" scale="0.85 0.85 0.85" />
      </geometry>
      <material name="hand_l_material_19">
        <color rgba="1 1 1 1" />
      </material>
    </visual>
    <visual name="hand_l_visual_20">
      <origin xyz="0 0 0" rpy="1.57079633 0 0" />
      <geometry>
        <mesh filename="Geometry/metacarpal5_lvs.obj" scale="0.85 0.85 0.85" />
      </geometry>
      <material name="hand_l_material_20">
        <color rgba="1 1 1 1" />
      </material>
    </visual>
    <visual name="hand_l_visual_21">
      <origin xyz="0 0 0" rpy="1.57079633 0 0" />
      <geometry>
        <mesh filename="Geometry/little_proximal_lvs.obj" scale="0.85 0.85 0.85" />
      </geometry>
      <material name="hand_l_material_21">
        <color rgba="1 1 1 1" />
      </material>
    </visual>
    <visual name="hand_l_visual_22">
      <origin xyz="0 0 0" rpy="1.57079633 0 0" />
      <geometry>
        <mesh filename="Geometry/little_medial_lvs.obj" scale="0.85 0.85 0.85" />
      </geometry>
      <material name="hand_l_material_22">
        <color rgba="1 1 1 1" />
      </material>
    </visual>
    <visual name="hand_l_visual_23">
      <origin xyz="0 0 0" rpy="1.57079633 0 0" />
      <geometry>
        <mesh filename="Geometry/little_distal_lvs.obj" scale="0.85 0.85 0.85" />
      </geometry>
      <material name="hand_l_material_23">
        <color rgba="1 1 1 1" />
      </material>
    </visual>
    <visual name="hand_l_visual_24">
      <origin xyz="0 0 0" rpy="1.57079633 0 0" />
      <geometry>
        <mesh filename="Geometry/metacarpal1_lvs.obj" scale="0.85 0.85 0.85" />
      </geometry>
      <material name="hand_l_material_24">
        <color rgba="1 1 1 1" />
      </material>
    </visual>
    <visual name="hand_l_visual_25">
      <origin xyz="0 0 0" rpy="1.57079633 0 0" />
      <geometry>
        <mesh filename="Geometry/thumb_proximal_lvs.obj" scale="0.85 0.85 0.85" />
      </geometry>
      <material name="hand_l_material_25">
        <color rgba="1 1 1 1" />
      </material>
    </visual>
    <visual name="hand_l_visual_26">
      <origin xyz="0 0 0" rpy="1.57079633 0 0" />
      <geometry>
        <mesh filename="Geometry/thumb_distal_lvs.obj" scale="0.85 0.85 0.85" />
      </geometry>
      <material name="hand_l_material_26">
        <color rgba="1 1 1 1" />
      </material>
    </visual>
  </link>
</robot>